<?xml version="1.0" ?>
<robot xmlns:xacro="http://www.ros.org/wiki/xacro">
    <xacro:macro name="tray" params="">
        <link name="tray">
            <inertial>
                <origin xyz="0.000045 0.218468 -0.0000000000003836" rpy="0 0 0"/>
                <mass value="58.666118"/>
                <inertia ixx="2.038" ixy="0.000005613643" ixz="-0.000000000000003583" iyx="0.000005613643" iyy="5.914" iyz="-0.00000000000002564" izx="-0.000000000000003583" izy="-0.00000000000002564" izz="3.878"/>
            </inertial>
            <visual>
                <origin xyz="0 0 0" rpy="0 0 0"/>
                <geometry>
                    <mesh filename="package://sim_models/models/${model_class}/${model}/meshes/tray.stl" scale="0.001 0.001 0.001"/>
                </geometry>
                <material name="top_gray"/>
            </visual>
            <collision>
                <origin xyz="0 0 0" rpy="0 0 0"/>
                <geometry>
                    <mesh filename="package://sim_models/models/${model_class}/${model}/meshes/tray.stl" scale="0.001 0.001 0.001"/>
                </geometry>
            </collision>
        </link>

        <gazebo reference="tray">
            <material value="Gazebo/DarkGrey" />
        </gazebo>

        <link name="rotating_base_link">
            <inertial>
                <origin xyz="0.000045 0.218468 -0.0000000000003836" rpy="0 0 0"/>
                <mass value="58.666118"/>
                <inertia ixx="2.038" ixy="0.000005613643" ixz="-0.000000000000003583" iyx="0.000005613643" iyy="5.914" iyz="-0.00000000000002564" izx="-0.000000000000003583" izy="-0.00000000000002564" izz="3.878"/>
            </inertial>
        </link>

        <joint name="tray_revolute_joint" type="revolute">
            <parent link="base_link"/>
            <child link="rotating_base_link"/>
            <origin xyz="0 0 0" rpy="0 0 0"/>
            <axis xyz="0 1 0"/>
            <limit effort="5886" velocity="${300*(3.14/180)}" lower="-6.28" upper="6.28"/>
            <dynamics damping="0.5" friction="0.1"/>
        </joint>

        <joint name="tray_prismatic_joint" type="prismatic">
            <parent link="rotating_base_link"/>
            <child link="tray"/>
            <origin xyz="0 0 0" rpy="0 0 0"/>
            <axis xyz="0 1 0"/>
            <limit effort="5886" velocity="0.013" lower="0" upper="0.06"/>
        </joint>
    </xacro:macro>
</robot>