<?xml version="1.0" ?>
<!-- =================================================================================== -->
<!-- |    This document was autogenerated by xacro from W3-600B.xacro                  | -->
<!-- |    EDITING THIS FILE BY HAND IS NOT RECOMMENDED                                 | -->
<!-- =================================================================================== -->
<robot name="W3-600B">
  <!-- <xacro:property name="caster_support_z_offset" value="0"/>

<xacro:property name="caster_wheel_x_offset" value="0"/>
<xacro:property name="caster_wheel_y_offset" value="0"/>
<xacro:property name="caster_wheel_z_offset" value="0"/> -->
  <material name="silver">
    <color rgba="0.700 0.700 0.700 1.000"/>
  </material>
  <gazebo>
    <plugin filename="libgazebo_ros_control.so" name="control"/>
  </gazebo>
  <gazebo reference="base_link">
    <material>Gazebo/Silver</material>
    <mu1>0.2</mu1>
    <mu2>0.2</mu2>
    <selfCollide>true</selfCollide>
    <gravity>true</gravity>
  </gazebo>
  <link name="base_link">
    <inertial>
      <origin rpy="0 0 0" xyz="-0.001608 0.058048 -0.000259"/>
      <mass value="69.363439"/>
      <inertia ixx="3.742" ixy="-0.001876" ixz="0.001144" iyx="-0.001876" iyy="9.426" iyz="0.0002847" izx="0.001144" izy="0.0002847" izz="6.169"/>
    </inertial>
    <visual>
      <origin rpy="0 0 0" xyz="0 0 0"/>
      <geometry>
        <mesh filename="package://W3-600B/meshes/base_link_v2.stl" scale="0.001 0.001 0.001"/>
      </geometry>
      <material name="silver"/>
    </visual>
    <collision>
      <origin rpy="0 0 0" xyz="0 0 0"/>
      <geometry>
        <mesh filename="package://W3-600B/meshes/base_link_v2.stl" scale="0.001 0.001 0.001"/>
      </geometry>
    </collision>
  </link>
  <!-- BACK RIGHT CASTER -->
  <link name="caster_wheel_br_1">
    <inertial>
      <origin rpy="0 0 0" xyz="-0.308999 0.013101 0.26168"/>
      <mass value="0.648186"/>
      <inertia ixx="0.0002538" ixy="-0.000000037013" ixz="6.025E-16" iyx="-0.000000037013" iyy="0.0002526" iyz="7.958E-16" izx="6.025E-16" izy="7.958E-16" izz="0.0004553"/>
    </inertial>
    <visual>
      <origin rpy="0 0 0" xyz="0 0 0"/>
      <geometry>
        <mesh filename="package://W3-600B/meshes/MANIFOLD_SOLID_BREP_6641.stl" scale="0.001 0.001 0.001"/>
      </geometry>
      <material name="silver"/>
    </visual>
    <collision>
      <origin rpy="0 0 0" xyz="0 0 0"/>
      <geometry>
        <mesh filename="package://W3-600B/meshes/MANIFOLD_SOLID_BREP_6641.stl" scale="0.001 0.001 0.001"/>
      </geometry>
    </collision>
  </link>
  <link name="caster_wheel_br_2">
    <inertial>
      <origin rpy="0 0 0" xyz="-0.309 0.013101 0.234319"/>
      <mass value="0.648234"/>
      <inertia ixx="0.0002539" ixy="-0.000000037121" ixz="-0.00000000479" iyx="-0.000000037121" iyy="0.0002526" iyz="-0.00000000012" izx="-0.00000000479" izy="-0.00000000012" izz="0.0004553"/>
    </inertial>
    <visual>
      <origin rpy="0 0 0" xyz="0 0 0"/>
      <geometry>
        <mesh filename="package://W3-600B/meshes/MANIFOLD_SOLID_BREP_7274.stl" scale="0.001 0.001 0.001"/>
      </geometry>
      <material name="silver"/>
    </visual>
    <collision>
      <origin rpy="0 0 0" xyz="0 0 0"/>
      <geometry>
        <mesh filename="package://W3-600B/meshes/MANIFOLD_SOLID_BREP_7274.stl" scale="0.001 0.001 0.001"/>
      </geometry>
    </collision>
  </link>
  <link name="caster_support_br">
    <inertial>
      <origin rpy="0 0 0" xyz="-0.290988 0.064338 0.24807"/>
      <mass value="1.304324"/>
      <inertia ixx="0.001114" ixy="-0.0001204" ixz="0.000001652803" iyx="-0.0001204" iyy="0.001351" iyz="0.000004703024" izx="0.000001652803" izy="0.000004703024" izz="0.001151"/>
    </inertial>
    <visual>
      <origin rpy="0 0 0" xyz="-0.02 -0.0685 0"/>
      <geometry>
        <mesh filename="package://W3-600B/meshes/BREP_WITH_VOIDS_6008.stl" scale="0.001 0.001 0.001"/>
      </geometry>
      <material name="silver"/>
    </visual>
    <collision>
      <origin rpy="0 0 0" xyz="-0.02 -0.0685 0"/>
      <geometry>
        <mesh filename="package://W3-600B/meshes/BREP_WITH_VOIDS_6008.stl" scale="0.001 0.001 0.001"/>
      </geometry>
    </collision>
  </link>
  <!-- support joint -->
  <joint name="caster_support_br_joint" type="continuous">
    <parent link="base_link"/>
    <child link="caster_support_br"/>
    <origin rpy="0 0 0" xyz="-0.289 0.0816 0.248"/>
    <axis xyz="0 1 0"/>
  </joint>
  <!-- 1 wheel -->
  <joint name="caster_wheel_br_1_joint" type="continuous">
    <parent link="caster_support_br"/>
    <child link="caster_wheel_br_1"/>
    <origin rpy="0 0 0" xyz="-0.02 -0.0685 0"/>
    <axis xyz="0 0 1"/>
  </joint>
  <!-- 2 wheel -->
  <joint name="caster_wheel_br_2_joint" type="continuous">
    <parent link="caster_support_br"/>
    <child link="caster_wheel_br_2"/>
    <origin rpy="0 0 0" xyz="-0.02 -0.0685 0"/>
    <axis xyz="0 0 1"/>
  </joint>
  <!-- <xacro:fr_caster_wheel/>
<xacro:fl_caster_wheel/> -->
  <link name="bottom_camera">
    <inertial>
      <origin rpy="0 0 0" xyz="0 0.076527 0.001765"/>
      <mass value="1.384936"/>
      <inertia ixx="0.00104" ixy="-7.659E-17" ixz="-0.000000000000008721" iyx="-7.659E-17" iyy="0.001219" iyz="-0.000010728685" izx="-0.000000000000008721" izy="-0.000010728685" izz="0.0005682"/>
    </inertial>
    <visual>
      <origin rpy="0 0 0" xyz="0 0 0"/>
      <geometry>
        <mesh filename="package://W3-600B/meshes/bottom_camera.stl" scale="0.001 0.001 0.001"/>
      </geometry>
      <material name="silver"/>
    </visual>
    <collision>
      <origin rpy="0 0 0" xyz="0 0 0"/>
      <geometry>
        <mesh filename="package://W3-600B/meshes/bottom_camera.stl" scale="0.001 0.001 0.001"/>
      </geometry>
    </collision>
  </link>
  <link name="up_camera">
    <inertial>
      <origin rpy="0 0 0" xyz="0 0.148473 0.001765"/>
      <mass value="1.384936"/>
      <inertia ixx="0.00104" ixy="-7.659E-17" ixz="0.000000000000008721" iyx="-7.659E-17" iyy="0.001219" iyz="0.000010728685" izx="0.000000000000008721" izy="0.000010728685" izz="0.0005682"/>
    </inertial>
    <visual>
      <origin rpy="0 0 0" xyz="0 0 0"/>
      <geometry>
        <mesh filename="package://W3-600B/meshes/up_camera.stl" scale="0.001 0.001 0.001"/>
      </geometry>
      <material name="silver"/>
    </visual>
    <collision>
      <origin rpy="0 0 0" xyz="0 0 0"/>
      <geometry>
        <mesh filename="package://W3-600B/meshes/up_camera.stl" scale="0.001 0.001 0.001"/>
      </geometry>
    </collision>
  </link>
  <link name="back_lidar">
    <inertial>
      <origin rpy="0 0 0" xyz="-0.42659 0.151334 0"/>
      <mass value="1.188679"/>
      <inertia ixx="0.0007557" ixy="0.000000605351" ixz="-1.051E-17" iyx="0.000000605351" iyy="0.000412" iyz="8.925E-18" izx="-1.051E-17" izy="8.925E-18" izz="0.0007558"/>
    </inertial>
    <visual>
      <origin rpy="0 0 0" xyz="0 0 0"/>
      <geometry>
        <mesh filename="package://W3-600B/meshes/lidar.stl" scale="0.001 0.001 0.001"/>
      </geometry>
      <material name="silver"/>
    </visual>
    <collision>
      <origin rpy="0 0 0" xyz="0 0 0"/>
      <geometry>
        <mesh filename="package://W3-600B/meshes/lidar.stl" scale="0.001 0.001 0.001"/>
      </geometry>
    </collision>
  </link>
  <link name="front_lidar">
    <inertial>
      <origin rpy="0 0 0" xyz="0.423797 0.139017 0.011563"/>
      <mass value="0.569677"/>
      <inertia ixx="0.0009071" ixy="0.000000243534" ixz="0.000014337829" iyx="0.000000243534" iyy="0.0008086" iyz="0.000074824692" izx="0.000014337829" izy="0.000074824692" izz="0.0005095"/>
    </inertial>
    <visual>
      <origin rpy="0 1.57 0" xyz="0.424631 0.1165 0"/>
      <geometry>
        <mesh filename="package://W3-600B/meshes/front_lidar.stl" scale="0.001 0.001 0.001"/>
      </geometry>
      <material name="silver"/>
    </visual>
    <collision>
      <origin rpy="0 1.57 0" xyz="0.424631 0.1165 0"/>
      <geometry>
        <mesh filename="package://W3-600B/meshes/front_lidar.stl" scale="0.001 0.001 0.001"/>
      </geometry>
    </collision>
  </link>
  <link name="left_wheel">
    <inertial>
      <origin rpy="0 0 0" xyz="-0.000216 0.057568 -0.271782"/>
      <mass value="9.185826"/>
      <inertia ixx="0.02957" ixy="-0.000044741546" ixz="0.0001326" iyx="-0.000044741546" iyy="0.03102" iyz="0.000007781675" izx="0.0001326" izy="0.000007781675" izz="0.02782"/>
    </inertial>
    <visual>
      <origin rpy="0 0 0" xyz="0 0.0575 -0.131553"/>
      <geometry>
        <mesh filename="package://W3-600B/meshes/left_wheel.stl" scale="0.001 0.001 0.001"/>
      </geometry>
      <material name="silver"/>
    </visual>
    <collision>
      <origin rpy="0 0 0" xyz="0 0.0575 -0.131553"/>
      <geometry>
        <mesh filename="package://W3-600B/meshes/left_wheel.stl" scale="0.001 0.001 0.001"/>
      </geometry>
    </collision>
  </link>
  <link name="right_wheel">
    <inertial>
      <origin rpy="0 0 0" xyz="0.000216 0.057568 0.271782"/>
      <mass value="9.185826"/>
      <inertia ixx="0.02957" ixy="0.000044741546" ixz="0.0001326" iyx="0.000044741546" iyy="0.03102" iyz="-0.000007781675" izx="0.0001326" izy="-0.000007781675" izz="0.02782"/>
    </inertial>
    <visual>
      <origin rpy="0 3.14 0" xyz="0 0.0575 0.131553"/>
      <geometry>
        <mesh filename="package://W3-600B/meshes/right_wheel.stl" scale="0.001 0.001 0.001"/>
      </geometry>
      <material name="silver"/>
    </visual>
    <collision>
      <origin rpy="0 3.14 0" xyz="0 0.0575 0.131553"/>
      <geometry>
        <mesh filename="package://W3-600B/meshes/right_wheel.stl" scale="0.001 0.001 0.001"/>
      </geometry>
    </collision>
  </link>
  <!-- <link name="tray">
  <inertial>
    <origin xyz="0.000045 0.218468 -0.0000000000003836" rpy="0 0 0"/>
    <mass value="58.666118"/>
    <inertia ixx="2.038" ixy="0.000005613643" ixz="-0.000000000000003583" iyx="0.000005613643" iyy="5.914" iyz="-0.00000000000002564" izx="-0.000000000000003583" izy="-0.00000000000002564" izz="3.878"/>
  </inertial>
  <visual>
    <origin xyz="0 0 0" rpy="0 0 0"/>
    <geometry>
      <mesh filename="package://W3-600B/meshes/tray.stl" scale="0.001 0.001 0.001"/>
    </geometry>
    <material name="silver"/>
  </visual>
  <collision>
    <origin xyz="0 0 0" rpy="0 0 0"/>
    <geometry>
      <mesh filename="package://W3-600B/meshes/tray.stl" scale="0.001 0.001 0.001"/>
    </geometry>
  </collision>
</link> -->
</robot>
