<?xml version="1.0" ?>
<!-- =================================================================================== -->
<!-- |    This document was autogenerated by xacro from w3_600b.xacro                  | -->
<!-- |    EDITING THIS FILE BY HAND IS NOT RECOMMENDED                                 | -->
<!-- =================================================================================== -->
<robot name="w3_600b">
  <coppelia_file filename="/home/gilmar/sim/sim_ws/install/sim_models/share/sim_models/models/robots/w3_600b/files/CoppeliaSim/w3_600b.ttm"/>
  <!-- <xacro:property name="caster_support_z_offset" value="0"/>

  <xacro:property name="caster_wheel_x_offset" value="0"/>
  <xacro:property name="caster_wheel_y_offset" value="0"/>
  <xacro:property name="caster_wheel_z_offset" value="0"/> -->
  <!-- botão vermelho -->
  <!-- Material definitions -->
  <material name="blue_body">
    <color rgba="0.2 0.6 0.8 1.0"/>
  </material>
  <material name="dark_gray">
    <color rgba="0.2 0.2 0.2 1.0"/>
  </material>
  <material name="top_gray">
    <color rgba="0.6 0.6 0.6 1.0"/>
  </material>
  <material name="led_cyan">
    <color rgba="0.0 1.0 1.0 1.0"/>
  </material>
  <material name="led_pink">
    <color rgba="1.0 0.4 0.8 1.0"/>
  </material>
  <material name="button_green">
    <color rgba="0.0 0.8 0.0 1.0"/>
  </material>
  <material name="button_red">
    <color rgba="0.8 0.0 0.0 1.0"/>
  </material>
  <material name="silver">
    <color rgba="0.700 0.700 0.700 1.000"/>
  </material>
  <!-- STRUCTURE -->
  <link name="world_link"/>
  <link name="base_link">
    <inertial>
      <origin rpy="0 0 0" xyz="-0.001608 0.058048 -0.000259"/>
      <mass value="69.363439"/>
      <inertia ixx="3.742" ixy="-0.001876" ixz="0.001144" iyx="-0.001876" iyy="9.426" iyz="0.0002847" izx="0.001144" izy="0.0002847" izz="6.169"/>
    </inertial>
    <visual>
      <origin rpy="0 0 0" xyz="0 0 0"/>
      <geometry>
        <mesh filename="package://sim_models/models/robots/w3_600b/meshes/base_link_v2.stl" scale="0.001 0.001 0.001"/>
      </geometry>
      <material name="blue_body"/>
    </visual>
    <collision>
      <origin rpy="0 0 0" xyz="0 0 0"/>
      <geometry>
        <mesh filename="package://sim_models/models/robots/w3_600b/meshes/base_link_v2.stl" scale="0.001 0.001 0.001"/>
      </geometry>
    </collision>
  </link>
  <joint name="base_to_world" type="fixed">
    <parent link="world_link"/>
    <child link="base_link"/>
    <origin rpy="1.57 0 0" xyz="0 0 0"/>
  </joint>
  <!-- BACK RIGHT CASTER -->
  <link name="caster_wheel_br_1">
    <inertial>
      <origin rpy="0 0 0" xyz="0.0 0.0 0.013679895"/>
      <mass value="0.648186"/>
      <inertia ixx="32.110336" ixy="-0.000001493513" ixz="-0.000011677849" iyy="32.098568" iyz="0.000000016651" izz="57.71662"/>
    </inertial>
    <visual>
      <origin rpy="0 0 0" xyz="0 0 0"/>
      <geometry>
        <mesh filename="package://sim_models/models/robots/w3_600b/meshes/MANIFOLD_SOLID_BREP_6641.stl" scale="0.001 0.001 0.001"/>
      </geometry>
      <material name="dark_gray"/>
    </visual>
    <collision>
      <origin rpy="0 0 0" xyz="0 0 0"/>
      <geometry>
        <mesh filename="package://sim_models/models/robots/w3_600b/meshes/MANIFOLD_SOLID_BREP_6641.stl" scale="0.001 0.001 0.001"/>
      </geometry>
    </collision>
  </link>
  <link name="caster_wheel_br_2">
    <inertial>
      <origin rpy="0 0 0" xyz="0.0 0.0 0.013679895"/>
      <mass value="0.648234"/>
      <inertia ixx="32.110336" ixy="-0.000001493513" ixz="-0.000011677849" iyy="32.098568" iyz="0.000000016651" izz="57.71662"/>
    </inertial>
    <visual>
      <origin rpy="0 0 0" xyz="0 0 0"/>
      <geometry>
        <mesh filename="package://sim_models/models/robots/w3_600b/meshes/MANIFOLD_SOLID_BREP_7274.stl" scale="0.001 0.001 0.001"/>
      </geometry>
      <material name="dark_gray"/>
    </visual>
    <collision>
      <origin rpy="0 0 0" xyz="0 0 0"/>
      <geometry>
        <mesh filename="package://sim_models/models/robots/w3_600b/meshes/MANIFOLD_SOLID_BREP_7274.stl" scale="0.001 0.001 0.001"/>
      </geometry>
    </collision>
  </link>
  <link name="caster_support_br">
    <inertial>
      <origin rpy="0 0 0" xyz="0.018014271 0.051245800 0.000070723"/>
      <mass value="1.304324"/>
      <inertia ixx="141.765056" ixy="-15.302794" ixz="0.211610422" iyy="172.001216" iyz="0.60176325" izz="146.500608"/>
    </inertial>
    <visual>
      <origin rpy="0 0 0" xyz="-0.02 -0.0685 0"/>
      <geometry>
        <mesh filename="package://sim_models/models/robots/w3_600b/meshes/BREP_WITH_VOIDS_6008.stl" scale="0.001 0.001 0.001"/>
      </geometry>
      <material name="silver"/>
    </visual>
    <!-- <collision>
                <origin xyz="${-caster_support_x_offset} ${-caster_support_y_offset} 0" rpy="0 0 0"/>
                <geometry>
                    <mesh filename="package://sim_models/models/${model_class}/${model}/meshes/BREP_WITH_VOIDS_6008.stl" scale="0.001 0.001 0.001"/>
                </geometry>
            </collision> -->
  </link>
  <joint name="caster_support_br_joint" type="continuous">
    <parent link="base_link"/>
    <child link="caster_support_br"/>
    <origin rpy="0 0 0" xyz="-0.289 0.0816 0.248"/>
    <axis xyz="0 1 0"/>
  </joint>
  <!-- 1 wheel -->
  <joint name="caster_wheel_br_1_joint" type="continuous">
    <parent link="caster_support_br"/>
    <child link="caster_wheel_br_1"/>
    <origin rpy="0 0 0" xyz="-0.02 -0.0685 0"/>
    <axis xyz="0 0 1"/>
  </joint>
  <!-- 2 wheel -->
  <joint name="caster_wheel_br_2_joint" type="continuous">
    <parent link="caster_support_br"/>
    <child link="caster_wheel_br_2"/>
    <origin rpy="0 0 0" xyz="-0.02 -0.0685 0"/>
    <axis xyz="0 0 1"/>
  </joint>
  <!-- BACK RIGHT CASTER -->
  <link name="caster_wheel_bl_1">
    <inertial>
      <origin rpy="0 0 0" xyz="0.0 0.0 0.013679895"/>
      <mass value="0.648186"/>
      <inertia ixx="32.110336" ixy="-0.000001493513" ixz="-0.000011677849" iyy="32.098568" iyz="0.000000016651" izz="57.71662"/>
    </inertial>
    <visual>
      <origin rpy="0 0 0" xyz="0 0 0"/>
      <geometry>
        <mesh filename="package://sim_models/models/robots/w3_600b/meshes/MANIFOLD_SOLID_BREP_6641.stl" scale="0.001 0.001 0.001"/>
      </geometry>
      <material name="dark_gray"/>
    </visual>
    <collision>
      <origin rpy="0 0 0" xyz="0 0 0"/>
      <geometry>
        <mesh filename="package://sim_models/models/robots/w3_600b/meshes/MANIFOLD_SOLID_BREP_6641.stl" scale="0.001 0.001 0.001"/>
      </geometry>
    </collision>
  </link>
  <link name="caster_wheel_bl_2">
    <inertial>
      <origin rpy="0 0 0" xyz="0.0 0.0 0.013679895"/>
      <mass value="0.648234"/>
      <inertia ixx="32.110336" ixy="-0.000001493513" ixz="-0.000011677849" iyy="32.098568" iyz="0.000000016651" izz="57.71662"/>
    </inertial>
    <visual>
      <origin rpy="0 0 0" xyz="0 0 0"/>
      <geometry>
        <mesh filename="package://sim_models/models/robots/w3_600b/meshes/MANIFOLD_SOLID_BREP_7274.stl" scale="0.001 0.001 0.001"/>
      </geometry>
      <material name="dark_gray"/>
    </visual>
    <collision>
      <origin rpy="0 0 0" xyz="0 0 0"/>
      <geometry>
        <mesh filename="package://sim_models/models/robots/w3_600b/meshes/MANIFOLD_SOLID_BREP_7274.stl" scale="0.001 0.001 0.001"/>
      </geometry>
    </collision>
  </link>
  <link name="caster_support_bl">
    <inertial>
      <origin rpy="0 0 0" xyz="0.018014271 0.051245800 0.000070723"/>
      <mass value="1.304324"/>
      <inertia ixx="141.765056" ixy="-15.302794" ixz="0.211610422" iyy="172.001216" iyz="0.60176325" izz="146.500608"/>
    </inertial>
    <visual>
      <origin rpy="0 0 0" xyz="-0.02 -0.0685 0"/>
      <geometry>
        <mesh filename="package://sim_models/models/robots/w3_600b/meshes/BREP_WITH_VOIDS_6008.stl" scale="0.001 0.001 0.001"/>
      </geometry>
      <material name="silver"/>
    </visual>
    <!-- <collision>
                <origin xyz="${-caster_support_x_offset} ${-caster_support_y_offset} 0" rpy="0 0 0"/>
                <geometry>
                    <mesh filename="package://sim_models/models/${model_class}/${model}/meshes/BREP_WITH_VOIDS_6008.stl" scale="0.001 0.001 0.001"/>
                </geometry>
            </collision> -->
  </link>
  <joint name="caster_support_bl_joint" type="continuous">
    <parent link="base_link"/>
    <child link="caster_support_bl"/>
    <origin rpy="0 0 0" xyz="-0.289 0.0816 -0.24800000000000003"/>
    <axis xyz="0 1 0"/>
  </joint>
  <!-- 1 wheel -->
  <joint name="caster_wheel_bl_1_joint" type="continuous">
    <parent link="caster_support_bl"/>
    <child link="caster_wheel_bl_1"/>
    <origin rpy="0 0 0" xyz="-0.02 -0.0685 0"/>
    <axis xyz="0 0 1"/>
  </joint>
  <!-- 2 wheel -->
  <joint name="caster_wheel_bl_2_joint" type="continuous">
    <parent link="caster_support_bl"/>
    <child link="caster_wheel_bl_2"/>
    <origin rpy="0 0 0" xyz="-0.02 -0.0685 0"/>
    <axis xyz="0 0 1"/>
  </joint>
  <!-- BACK RIGHT CASTER -->
  <link name="caster_wheel_fr_1">
    <inertial>
      <origin rpy="0 0 0" xyz="0.0 0.0 0.013679895"/>
      <mass value="0.648186"/>
      <inertia ixx="32.110336" ixy="-0.000001493513" ixz="-0.000011677849" iyy="32.098568" iyz="0.000000016651" izz="57.71662"/>
    </inertial>
    <visual>
      <origin rpy="0 0 0" xyz="0 0 0"/>
      <geometry>
        <mesh filename="package://sim_models/models/robots/w3_600b/meshes/MANIFOLD_SOLID_BREP_6641.stl" scale="0.001 0.001 0.001"/>
      </geometry>
      <material name="dark_gray"/>
    </visual>
    <collision>
      <origin rpy="0 0 0" xyz="0 0 0"/>
      <geometry>
        <mesh filename="package://sim_models/models/robots/w3_600b/meshes/MANIFOLD_SOLID_BREP_6641.stl" scale="0.001 0.001 0.001"/>
      </geometry>
    </collision>
  </link>
  <link name="caster_wheel_fr_2">
    <inertial>
      <origin rpy="0 0 0" xyz="0.0 0.0 0.013679895"/>
      <mass value="0.648234"/>
      <inertia ixx="32.110336" ixy="-0.000001493513" ixz="-0.000011677849" iyy="32.098568" iyz="0.000000016651" izz="57.71662"/>
    </inertial>
    <visual>
      <origin rpy="0 0 0" xyz="0 0 0"/>
      <geometry>
        <mesh filename="package://sim_models/models/robots/w3_600b/meshes/MANIFOLD_SOLID_BREP_7274.stl" scale="0.001 0.001 0.001"/>
      </geometry>
      <material name="dark_gray"/>
    </visual>
    <collision>
      <origin rpy="0 0 0" xyz="0 0 0"/>
      <geometry>
        <mesh filename="package://sim_models/models/robots/w3_600b/meshes/MANIFOLD_SOLID_BREP_7274.stl" scale="0.001 0.001 0.001"/>
      </geometry>
    </collision>
  </link>
  <link name="caster_support_fr">
    <inertial>
      <origin rpy="0 0 0" xyz="0.018014271 0.051245800 0.000070723"/>
      <mass value="1.304324"/>
      <inertia ixx="141.765056" ixy="-15.302794" ixz="0.211610422" iyy="172.001216" iyz="0.60176325" izz="146.500608"/>
    </inertial>
    <visual>
      <origin rpy="0 0 0" xyz="-0.02 -0.0685 0"/>
      <geometry>
        <mesh filename="package://sim_models/models/robots/w3_600b/meshes/BREP_WITH_VOIDS_6008.stl" scale="0.001 0.001 0.001"/>
      </geometry>
      <material name="silver"/>
    </visual>
    <!-- <collision>
                <origin xyz="${-caster_support_x_offset} ${-caster_support_y_offset} 0" rpy="0 0 0"/>
                <geometry>
                    <mesh filename="package://sim_models/models/${model_class}/${model}/meshes/BREP_WITH_VOIDS_6008.stl" scale="0.001 0.001 0.001"/>
                </geometry>
            </collision> -->
  </link>
  <joint name="caster_support_fr_joint" type="continuous">
    <parent link="base_link"/>
    <child link="caster_support_fr"/>
    <origin rpy="0 0 0" xyz="0.335 0.0816 0.177"/>
    <axis xyz="0 1 0"/>
  </joint>
  <!-- 1 wheel -->
  <joint name="caster_wheel_fr_1_joint" type="continuous">
    <parent link="caster_support_fr"/>
    <child link="caster_wheel_fr_1"/>
    <origin rpy="0 0 0" xyz="-0.02 -0.0685 0"/>
    <axis xyz="0 0 1"/>
  </joint>
  <!-- 2 wheel -->
  <joint name="caster_wheel_fr_2_joint" type="continuous">
    <parent link="caster_support_fr"/>
    <child link="caster_wheel_fr_2"/>
    <origin rpy="0 0 0" xyz="-0.02 -0.0685 0"/>
    <axis xyz="0 0 1"/>
  </joint>
  <!-- BACK RIGHT CASTER -->
  <link name="caster_wheel_fl_1">
    <inertial>
      <origin rpy="0 0 0" xyz="0.0 0.0 0.013679895"/>
      <mass value="0.648186"/>
      <inertia ixx="32.110336" ixy="-0.000001493513" ixz="-0.000011677849" iyy="32.098568" iyz="0.000000016651" izz="57.71662"/>
    </inertial>
    <visual>
      <origin rpy="0 0 0" xyz="0 0 0"/>
      <geometry>
        <mesh filename="package://sim_models/models/robots/w3_600b/meshes/MANIFOLD_SOLID_BREP_6641.stl" scale="0.001 0.001 0.001"/>
      </geometry>
      <material name="dark_gray"/>
    </visual>
    <collision>
      <origin rpy="0 0 0" xyz="0 0 0"/>
      <geometry>
        <mesh filename="package://sim_models/models/robots/w3_600b/meshes/MANIFOLD_SOLID_BREP_6641.stl" scale="0.001 0.001 0.001"/>
      </geometry>
    </collision>
  </link>
  <link name="caster_wheel_fl_2">
    <inertial>
      <origin rpy="0 0 0" xyz="0.0 0.0 0.013679895"/>
      <mass value="0.648234"/>
      <inertia ixx="32.110336" ixy="-0.000001493513" ixz="-0.000011677849" iyy="32.098568" iyz="0.000000016651" izz="57.71662"/>
    </inertial>
    <visual>
      <origin rpy="0 0 0" xyz="0 0 0"/>
      <geometry>
        <mesh filename="package://sim_models/models/robots/w3_600b/meshes/MANIFOLD_SOLID_BREP_7274.stl" scale="0.001 0.001 0.001"/>
      </geometry>
      <material name="dark_gray"/>
    </visual>
    <collision>
      <origin rpy="0 0 0" xyz="0 0 0"/>
      <geometry>
        <mesh filename="package://sim_models/models/robots/w3_600b/meshes/MANIFOLD_SOLID_BREP_7274.stl" scale="0.001 0.001 0.001"/>
      </geometry>
    </collision>
  </link>
  <link name="caster_support_fl">
    <inertial>
      <origin rpy="0 0 0" xyz="0.018014271 0.051245800 0.000070723"/>
      <mass value="1.304324"/>
      <inertia ixx="141.765056" ixy="-15.302794" ixz="0.211610422" iyy="172.001216" iyz="0.60176325" izz="146.500608"/>
    </inertial>
    <visual>
      <origin rpy="0 0 0" xyz="-0.02 -0.0685 0"/>
      <geometry>
        <mesh filename="package://sim_models/models/robots/w3_600b/meshes/BREP_WITH_VOIDS_6008.stl" scale="0.001 0.001 0.001"/>
      </geometry>
      <material name="silver"/>
    </visual>
    <!-- <collision>
                <origin xyz="${-caster_support_x_offset} ${-caster_support_y_offset} 0" rpy="0 0 0"/>
                <geometry>
                    <mesh filename="package://sim_models/models/${model_class}/${model}/meshes/BREP_WITH_VOIDS_6008.stl" scale="0.001 0.001 0.001"/>
                </geometry>
            </collision> -->
  </link>
  <joint name="caster_support_fl_joint" type="continuous">
    <parent link="base_link"/>
    <child link="caster_support_fl"/>
    <origin rpy="0 0 0" xyz="0.335 0.0816 -0.17700000000000002"/>
    <axis xyz="0 1 0"/>
  </joint>
  <!-- 1 wheel -->
  <joint name="caster_wheel_fl_1_joint" type="continuous">
    <parent link="caster_support_fl"/>
    <child link="caster_wheel_fl_1"/>
    <origin rpy="0 0 0" xyz="-0.02 -0.0685 0"/>
    <axis xyz="0 0 1"/>
  </joint>
  <!-- 2 wheel -->
  <joint name="caster_wheel_fl_2_joint" type="continuous">
    <parent link="caster_support_fl"/>
    <child link="caster_wheel_fl_2"/>
    <origin rpy="0 0 0" xyz="-0.02 -0.0685 0"/>
    <axis xyz="0 0 1"/>
  </joint>
  <!-- <xacro:camera name="downward"/>
  <xacro:camera name="upward"/>

  <xacro:lidar name="front" x="0.424631" y="0.1165" z="0"/>
  <xacro:lidar name="back" x="0" y="0" z="0"/> -->
  <link name="left_wheel">
    <inertial>
      <origin rpy="0 0 0" xyz="-0.000216 0.057568 -0.271782"/>
      <mass value="9.185826"/>
      <inertia ixx="0.02957" ixy="-0.000044741546" ixz="0.0001326" iyx="-0.000044741546" iyy="0.03102" iyz="0.000007781675" izx="0.0001326" izy="0.000007781675" izz="0.02782"/>
    </inertial>
    <visual>
      <origin rpy="0 0 0" xyz="0 0 0.147197"/>
      <geometry>
        <mesh filename="package://sim_models/models/robots/w3_600b/meshes/left_wheel.stl" scale="0.001 0.001 0.001"/>
      </geometry>
      <material name="dark_gray"/>
    </visual>
    <collision>
      <origin rpy="0 0 0" xyz="0 0 0.147197"/>
      <geometry>
        <mesh filename="package://sim_models/models/robots/w3_600b/meshes/left_wheel.stl" scale="0.001 0.001 0.001"/>
      </geometry>
    </collision>
  </link>
  <joint name="left_wheel_joint" type="revolute">
    <parent link="base_link"/>
    <child link="left_wheel"/>
    <origin rpy="0 0 0" xyz="0 0.0575 -0.27875"/>
    <limit effort="22" lower="-6.28" upper="6.28" velocity="219.8"/>
    <axis xyz="0 0 1"/>
  </joint>
  <link name="right_wheel">
    <inertial>
      <origin rpy="0 0 0" xyz="0.000216 0.057568 0.271782"/>
      <mass value="9.185826"/>
      <inertia ixx="0.02957" ixy="0.000044741546" ixz="0.0001326" iyx="0.000044741546" iyy="0.03102" iyz="-0.000007781675" izx="0.0001326" izy="-0.000007781675" izz="0.02782"/>
    </inertial>
    <visual>
      <origin rpy="0 0 0" xyz="0 0 0.147197"/>
      <geometry>
        <mesh filename="package://sim_models/models/robots/w3_600b/meshes/right_wheel.stl" scale="0.001 0.001 0.001"/>
      </geometry>
      <material name="dark_gray"/>
    </visual>
    <collision>
      <origin rpy="0 0 0" xyz="0 0 0.147197"/>
      <geometry>
        <mesh filename="package://sim_models/models/robots/w3_600b/meshes/right_wheel.stl" scale="0.001 0.001 0.001"/>
      </geometry>
    </collision>
  </link>
  <joint name="right_wheel_joint" type="revolute">
    <parent link="base_link"/>
    <child link="right_wheel"/>
    <origin rpy="0 3.14 0" xyz="0 0.0575 0.27875"/>
    <limit effort="22" lower="-6.28" upper="6.28" velocity="219.8"/>
    <axis xyz="0 0 1"/>
  </joint>
  <link name="tray">
    <inertial>
      <origin rpy="0 0 0" xyz="0.000045 0.218468 -0.0000000000003836"/>
      <mass value="58.666118"/>
      <inertia ixx="2.038" ixy="0.000005613643" ixz="-0.000000000000003583" iyx="0.000005613643" iyy="5.914" iyz="-0.00000000000002564" izx="-0.000000000000003583" izy="-0.00000000000002564" izz="3.878"/>
    </inertial>
    <visual>
      <origin rpy="0 0 0" xyz="0 0 0"/>
      <geometry>
        <mesh filename="package://sim_models/models/robots/w3_600b/meshes/tray.stl" scale="0.001 0.001 0.001"/>
      </geometry>
      <material name="top_gray"/>
    </visual>
    <collision>
      <origin rpy="0 0 0" xyz="0 0 0"/>
      <geometry>
        <mesh filename="package://sim_models/models/robots/w3_600b/meshes/tray.stl" scale="0.001 0.001 0.001"/>
      </geometry>
    </collision>
  </link>
  <link name="rotating_base_link">
    <inertial>
      <origin rpy="0 0 0" xyz="0.000045 0.218468 -0.0000000000003836"/>
      <mass value="58.666118"/>
      <inertia ixx="2.038" ixy="0.000005613643" ixz="-0.000000000000003583" iyx="0.000005613643" iyy="5.914" iyz="-0.00000000000002564" izx="-0.000000000000003583" izy="-0.00000000000002564" izz="3.878"/>
    </inertial>
  </link>
  <joint name="tray_revolute_joint" type="revolute">
    <parent link="base_link"/>
    <child link="rotating_base_link"/>
    <origin rpy="0 0 0" xyz="0 0 0"/>
    <axis xyz="0 1 0"/>
    <limit effort="5886" lower="-6.28" upper="6.28" velocity="5.233333333333334"/>
  </joint>
  <joint name="tray_prismatic_joint" type="prismatic">
    <parent link="rotating_base_link"/>
    <child link="tray"/>
    <origin rpy="0 0 0" xyz="0 0 0"/>
    <axis xyz="0 1 0"/>
    <limit effort="5886" lower="0" upper="0.06" velocity="0.013"/>
  </joint>
  <!-- CONTROL -->
  <ros2_control name="GazeboSystem" type="system">
    <hardware>
      <plugin>gazebo_ros2_control/GazeboSystem</plugin>
    </hardware>
    <joint name="left_wheel_joint">
      <command_interface name="velocity"/>
      <state_interface name="position"/>
      <state_interface name="velocity"/>
    </joint>
    <joint name="right_wheel_joint">
      <command_interface name="velocity"/>
      <state_interface name="velocity"/>
      <state_interface name="position"/>
    </joint>
    <joint name="tray_revolute_joint">
      <command_interface name="position"/>
      <state_interface name="position"/>
    </joint>
    <joint name="tray_prismatic_joint">
      <command_interface name="position"/>
      <state_interface name="position"/>
    </joint>
    <!-- <sensor name="imu_sensor">
      <state_interface name="orientation.x" />
      <state_interface name="orientation.y" />
      <state_interface name="orientation.z" />
      <state_interface name="orientation.w" />
      <state_interface name="angular_velocity.x" />
      <state_interface name="angular_velocity.y" />
      <state_interface name="angular_velocity.z" />
      <state_interface name="linear_acceleration.x" />
      <state_interface name="linear_acceleration.y" />
      <state_interface name="linear_acceleration.z" />
    </sensor> -->
  </ros2_control>
  <gazebo>
    <plugin filename="libgazebo_ros2_control.so" name="gazebo_ros2_control">
      <ros>
        <namespace>r2d2</namespace>
        <remapping>/r2d2/joint_states:=/joint_state_broadcaster/joint_states</remapping>
      </ros>
      <parameters>/home/gilmar/sim/sim_ws/install/sim_models/share/sim_models/models/robots/w3_600b/config/classic/w3_600b_controllers.yaml</parameters>
    </plugin>
  </gazebo>
</robot>
