<?xml version="1.0" ?>
<!-- =================================================================================== -->
<!-- |    This document was autogenerated by xacro from w3_600b.xacro                  | -->
<!-- |    EDITING THIS FILE BY HAND IS NOT RECOMMENDED                                 | -->
<!-- =================================================================================== -->
<robot name="w3_600b">
  <!-- <xacro:property name="caster_support_z_offset" value="0"/>

  <xacro:property name="caster_wheel_x_offset" value="0"/>
  <xacro:property name="caster_wheel_y_offset" value="0"/>
  <xacro:property name="caster_wheel_z_offset" value="0"/> -->
  <material name="silver">
    <color rgba="0.700 0.700 0.700 1.000"/>
  </material>
  <gazebo>
    <plugin filename="libgazebo_ros_control.so" name="control"/>
  </gazebo>
  <gazebo reference="base_link">
    <material>Gazebo/Silver</material>
    <mu1>0.2</mu1>
    <mu2>0.2</mu2>
    <selfCollide>true</selfCollide>
    <gravity>true</gravity>
  </gazebo>
  <!-- STRUCTURE -->
  <link name="base_link">
    <inertial>
      <origin rpy="0 0 0" xyz="-0.001608 0.058048 -0.000259"/>
      <mass value="69.363439"/>
      <inertia ixx="3.742" ixy="-0.001876" ixz="0.001144" iyx="-0.001876" iyy="9.426" iyz="0.0002847" izx="0.001144" izy="0.0002847" izz="6.169"/>
    </inertial>
    <visual>
      <origin rpy="0 0 0" xyz="0 0 0"/>
      <geometry>
        <mesh filename="package://w3_600b/meshes/base_link_v2.stl" scale="0.001 0.001 0.001"/>
      </geometry>
      <material name="silver"/>
    </visual>
    <collision>
      <origin rpy="0 0 0" xyz="0 0 0"/>
      <geometry>
        <mesh filename="package://w3_600b/meshes/base_link_v2.stl" scale="0.001 0.001 0.001"/>
      </geometry>
    </collision>
  </link>
  <!-- BACK RIGHT CASTER -->
  <link name="caster_wheel_br_1">
    <inertial>
      <origin rpy="0 0 0" xyz="0.0 0.0 0.013679895"/>
      <mass value="0.648186"/>
      <inertia ixx="32.110336" ixy="-0.000001493513" ixz="-0.000011677849" iyy="32.098568" iyz="0.000000016651" izz="57.71662"/>
    </inertial>
    <visual>
      <origin rpy="0 0 0" xyz="0 0 0"/>
      <geometry>
        <mesh filename="package://w3_600b/meshes/MANIFOLD_SOLID_BREP_6641.stl" scale="0.001 0.001 0.001"/>
      </geometry>
      <material name="silver"/>
    </visual>
    <collision>
      <origin rpy="0 0 0" xyz="0 0 0"/>
      <geometry>
        <mesh filename="package://w3_600b/meshes/MANIFOLD_SOLID_BREP_6641.stl" scale="0.001 0.001 0.001"/>
      </geometry>
    </collision>
  </link>
  <link name="caster_wheel_br_2">
    <inertial>
      <origin rpy="0 0 0" xyz="0.0 0.0 0.013679895"/>
      <mass value="0.648234"/>
      <inertia ixx="32.110336" ixy="-0.000001493513" ixz="-0.000011677849" iyy="32.098568" iyz="0.000000016651" izz="57.71662"/>
    </inertial>
    <visual>
      <origin rpy="0 0 0" xyz="0 0 0"/>
      <geometry>
        <mesh filename="package://w3_600b/meshes/MANIFOLD_SOLID_BREP_7274.stl" scale="0.001 0.001 0.001"/>
      </geometry>
      <material name="silver"/>
    </visual>
    <collision>
      <origin rpy="0 0 0" xyz="0 0 0"/>
      <geometry>
        <mesh filename="package://w3_600b/meshes/MANIFOLD_SOLID_BREP_7274.stl" scale="0.001 0.001 0.001"/>
      </geometry>
    </collision>
  </link>
  <link name="caster_support_br">
    <inertial>
      <origin rpy="0 0 0" xyz="0.018014271 0.051245800 0.000070723"/>
      <mass value="1.304324"/>
      <inertia ixx="141.765056" ixy="-15.302794" ixz="0.211610422" iyy="172.001216" iyz="0.60176325" izz="146.500608"/>
    </inertial>
    <visual>
      <origin rpy="0 0 0" xyz="-0.02 -0.0685 0"/>
      <geometry>
        <mesh filename="package://w3_600b/meshes/BREP_WITH_VOIDS_6008.stl" scale="0.001 0.001 0.001"/>
      </geometry>
      <material name="silver"/>
    </visual>
    <!-- <collision>
                <origin xyz="${-caster_support_x_offset} ${-caster_support_y_offset} 0" rpy="0 0 0"/>
                <geometry>
                    <mesh filename="package://w3_600b/meshes/BREP_WITH_VOIDS_6008.stl" scale="0.001 0.001 0.001"/>
                </geometry>
            </collision> -->
  </link>
  <joint name="caster_support_br_joint" type="continuous">
    <parent link="base_link"/>
    <child link="caster_support_br"/>
    <origin rpy="0 0 0" xyz="-0.289 0.0816 0.248"/>
    <axis xyz="0 1 0"/>
  </joint>
  <!-- 1 wheel -->
  <joint name="caster_wheel_br_1_joint" type="continuous">
    <parent link="caster_support_br"/>
    <child link="caster_wheel_br_1"/>
    <origin rpy="0 0 0" xyz="-0.02 -0.0685 0"/>
    <axis xyz="0 0 1"/>
  </joint>
  <!-- 2 wheel -->
  <joint name="caster_wheel_br_2_joint" type="continuous">
    <parent link="caster_support_br"/>
    <child link="caster_wheel_br_2"/>
    <origin rpy="0 0 0" xyz="-0.02 -0.0685 0"/>
    <axis xyz="0 0 1"/>
  </joint>
  <!-- BACK RIGHT CASTER -->
  <link name="caster_wheel_bl_1">
    <inertial>
      <origin rpy="0 0 0" xyz="0.0 0.0 0.013679895"/>
      <mass value="0.648186"/>
      <inertia ixx="32.110336" ixy="-0.000001493513" ixz="-0.000011677849" iyy="32.098568" iyz="0.000000016651" izz="57.71662"/>
    </inertial>
    <visual>
      <origin rpy="0 0 0" xyz="0 0 0"/>
      <geometry>
        <mesh filename="package://w3_600b/meshes/MANIFOLD_SOLID_BREP_6641.stl" scale="0.001 0.001 0.001"/>
      </geometry>
      <material name="silver"/>
    </visual>
    <collision>
      <origin rpy="0 0 0" xyz="0 0 0"/>
      <geometry>
        <mesh filename="package://w3_600b/meshes/MANIFOLD_SOLID_BREP_6641.stl" scale="0.001 0.001 0.001"/>
      </geometry>
    </collision>
  </link>
  <link name="caster_wheel_bl_2">
    <inertial>
      <origin rpy="0 0 0" xyz="0.0 0.0 0.013679895"/>
      <mass value="0.648234"/>
      <inertia ixx="32.110336" ixy="-0.000001493513" ixz="-0.000011677849" iyy="32.098568" iyz="0.000000016651" izz="57.71662"/>
    </inertial>
    <visual>
      <origin rpy="0 0 0" xyz="0 0 0"/>
      <geometry>
        <mesh filename="package://w3_600b/meshes/MANIFOLD_SOLID_BREP_7274.stl" scale="0.001 0.001 0.001"/>
      </geometry>
      <material name="silver"/>
    </visual>
    <collision>
      <origin rpy="0 0 0" xyz="0 0 0"/>
      <geometry>
        <mesh filename="package://w3_600b/meshes/MANIFOLD_SOLID_BREP_7274.stl" scale="0.001 0.001 0.001"/>
      </geometry>
    </collision>
  </link>
  <link name="caster_support_bl">
    <inertial>
      <origin rpy="0 0 0" xyz="0.018014271 0.051245800 0.000070723"/>
      <mass value="1.304324"/>
      <inertia ixx="141.765056" ixy="-15.302794" ixz="0.211610422" iyy="172.001216" iyz="0.60176325" izz="146.500608"/>
    </inertial>
    <visual>
      <origin rpy="0 0 0" xyz="-0.02 -0.0685 0"/>
      <geometry>
        <mesh filename="package://w3_600b/meshes/BREP_WITH_VOIDS_6008.stl" scale="0.001 0.001 0.001"/>
      </geometry>
      <material name="silver"/>
    </visual>
    <!-- <collision>
                <origin xyz="${-caster_support_x_offset} ${-caster_support_y_offset} 0" rpy="0 0 0"/>
                <geometry>
                    <mesh filename="package://w3_600b/meshes/BREP_WITH_VOIDS_6008.stl" scale="0.001 0.001 0.001"/>
                </geometry>
            </collision> -->
  </link>
  <joint name="caster_support_bl_joint" type="continuous">
    <parent link="base_link"/>
    <child link="caster_support_bl"/>
    <origin rpy="0 0 0" xyz="-0.289 0.0816 -0.24800000000000003"/>
    <axis xyz="0 1 0"/>
  </joint>
  <!-- 1 wheel -->
  <joint name="caster_wheel_bl_1_joint" type="continuous">
    <parent link="caster_support_bl"/>
    <child link="caster_wheel_bl_1"/>
    <origin rpy="0 0 0" xyz="-0.02 -0.0685 0"/>
    <axis xyz="0 0 1"/>
  </joint>
  <!-- 2 wheel -->
  <joint name="caster_wheel_bl_2_joint" type="continuous">
    <parent link="caster_support_bl"/>
    <child link="caster_wheel_bl_2"/>
    <origin rpy="0 0 0" xyz="-0.02 -0.0685 0"/>
    <axis xyz="0 0 1"/>
  </joint>
  <!-- BACK RIGHT CASTER -->
  <link name="caster_wheel_fr_1">
    <inertial>
      <origin rpy="0 0 0" xyz="0.0 0.0 0.013679895"/>
      <mass value="0.648186"/>
      <inertia ixx="32.110336" ixy="-0.000001493513" ixz="-0.000011677849" iyy="32.098568" iyz="0.000000016651" izz="57.71662"/>
    </inertial>
    <visual>
      <origin rpy="0 0 0" xyz="0 0 0"/>
      <geometry>
        <mesh filename="package://w3_600b/meshes/MANIFOLD_SOLID_BREP_6641.stl" scale="0.001 0.001 0.001"/>
      </geometry>
      <material name="silver"/>
    </visual>
    <collision>
      <origin rpy="0 0 0" xyz="0 0 0"/>
      <geometry>
        <mesh filename="package://w3_600b/meshes/MANIFOLD_SOLID_BREP_6641.stl" scale="0.001 0.001 0.001"/>
      </geometry>
    </collision>
  </link>
  <link name="caster_wheel_fr_2">
    <inertial>
      <origin rpy="0 0 0" xyz="0.0 0.0 0.013679895"/>
      <mass value="0.648234"/>
      <inertia ixx="32.110336" ixy="-0.000001493513" ixz="-0.000011677849" iyy="32.098568" iyz="0.000000016651" izz="57.71662"/>
    </inertial>
    <visual>
      <origin rpy="0 0 0" xyz="0 0 0"/>
      <geometry>
        <mesh filename="package://w3_600b/meshes/MANIFOLD_SOLID_BREP_7274.stl" scale="0.001 0.001 0.001"/>
      </geometry>
      <material name="silver"/>
    </visual>
    <collision>
      <origin rpy="0 0 0" xyz="0 0 0"/>
      <geometry>
        <mesh filename="package://w3_600b/meshes/MANIFOLD_SOLID_BREP_7274.stl" scale="0.001 0.001 0.001"/>
      </geometry>
    </collision>
  </link>
  <link name="caster_support_fr">
    <inertial>
      <origin rpy="0 0 0" xyz="0.018014271 0.051245800 0.000070723"/>
      <mass value="1.304324"/>
      <inertia ixx="141.765056" ixy="-15.302794" ixz="0.211610422" iyy="172.001216" iyz="0.60176325" izz="146.500608"/>
    </inertial>
    <visual>
      <origin rpy="0 0 0" xyz="-0.02 -0.0685 0"/>
      <geometry>
        <mesh filename="package://w3_600b/meshes/BREP_WITH_VOIDS_6008.stl" scale="0.001 0.001 0.001"/>
      </geometry>
      <material name="silver"/>
    </visual>
    <!-- <collision>
                <origin xyz="${-caster_support_x_offset} ${-caster_support_y_offset} 0" rpy="0 0 0"/>
                <geometry>
                    <mesh filename="package://w3_600b/meshes/BREP_WITH_VOIDS_6008.stl" scale="0.001 0.001 0.001"/>
                </geometry>
            </collision> -->
  </link>
  <joint name="caster_support_fr_joint" type="continuous">
    <parent link="base_link"/>
    <child link="caster_support_fr"/>
    <origin rpy="0 0 0" xyz="0.335 0.0816 0.177"/>
    <axis xyz="0 1 0"/>
  </joint>
  <!-- 1 wheel -->
  <joint name="caster_wheel_fr_1_joint" type="continuous">
    <parent link="caster_support_fr"/>
    <child link="caster_wheel_fr_1"/>
    <origin rpy="0 0 0" xyz="-0.02 -0.0685 0"/>
    <axis xyz="0 0 1"/>
  </joint>
  <!-- 2 wheel -->
  <joint name="caster_wheel_fr_2_joint" type="continuous">
    <parent link="caster_support_fr"/>
    <child link="caster_wheel_fr_2"/>
    <origin rpy="0 0 0" xyz="-0.02 -0.0685 0"/>
    <axis xyz="0 0 1"/>
  </joint>
  <!-- BACK RIGHT CASTER -->
  <link name="caster_wheel_fl_1">
    <inertial>
      <origin rpy="0 0 0" xyz="0.0 0.0 0.013679895"/>
      <mass value="0.648186"/>
      <inertia ixx="32.110336" ixy="-0.000001493513" ixz="-0.000011677849" iyy="32.098568" iyz="0.000000016651" izz="57.71662"/>
    </inertial>
    <visual>
      <origin rpy="0 0 0" xyz="0 0 0"/>
      <geometry>
        <mesh filename="package://w3_600b/meshes/MANIFOLD_SOLID_BREP_6641.stl" scale="0.001 0.001 0.001"/>
      </geometry>
      <material name="silver"/>
    </visual>
    <collision>
      <origin rpy="0 0 0" xyz="0 0 0"/>
      <geometry>
        <mesh filename="package://w3_600b/meshes/MANIFOLD_SOLID_BREP_6641.stl" scale="0.001 0.001 0.001"/>
      </geometry>
    </collision>
  </link>
  <link name="caster_wheel_fl_2">
    <inertial>
      <origin rpy="0 0 0" xyz="0.0 0.0 0.013679895"/>
      <mass value="0.648234"/>
      <inertia ixx="32.110336" ixy="-0.000001493513" ixz="-0.000011677849" iyy="32.098568" iyz="0.000000016651" izz="57.71662"/>
    </inertial>
    <visual>
      <origin rpy="0 0 0" xyz="0 0 0"/>
      <geometry>
        <mesh filename="package://w3_600b/meshes/MANIFOLD_SOLID_BREP_7274.stl" scale="0.001 0.001 0.001"/>
      </geometry>
      <material name="silver"/>
    </visual>
    <collision>
      <origin rpy="0 0 0" xyz="0 0 0"/>
      <geometry>
        <mesh filename="package://w3_600b/meshes/MANIFOLD_SOLID_BREP_7274.stl" scale="0.001 0.001 0.001"/>
      </geometry>
    </collision>
  </link>
  <link name="caster_support_fl">
    <inertial>
      <origin rpy="0 0 0" xyz="0.018014271 0.051245800 0.000070723"/>
      <mass value="1.304324"/>
      <inertia ixx="141.765056" ixy="-15.302794" ixz="0.211610422" iyy="172.001216" iyz="0.60176325" izz="146.500608"/>
    </inertial>
    <visual>
      <origin rpy="0 0 0" xyz="-0.02 -0.0685 0"/>
      <geometry>
        <mesh filename="package://w3_600b/meshes/BREP_WITH_VOIDS_6008.stl" scale="0.001 0.001 0.001"/>
      </geometry>
      <material name="silver"/>
    </visual>
    <!-- <collision>
                <origin xyz="${-caster_support_x_offset} ${-caster_support_y_offset} 0" rpy="0 0 0"/>
                <geometry>
                    <mesh filename="package://w3_600b/meshes/BREP_WITH_VOIDS_6008.stl" scale="0.001 0.001 0.001"/>
                </geometry>
            </collision> -->
  </link>
  <joint name="caster_support_fl_joint" type="continuous">
    <parent link="base_link"/>
    <child link="caster_support_fl"/>
    <origin rpy="0 0 0" xyz="0.335 0.0816 -0.17700000000000002"/>
    <axis xyz="0 1 0"/>
  </joint>
  <!-- 1 wheel -->
  <joint name="caster_wheel_fl_1_joint" type="continuous">
    <parent link="caster_support_fl"/>
    <child link="caster_wheel_fl_1"/>
    <origin rpy="0 0 0" xyz="-0.02 -0.0685 0"/>
    <axis xyz="0 0 1"/>
  </joint>
  <!-- 2 wheel -->
  <joint name="caster_wheel_fl_2_joint" type="continuous">
    <parent link="caster_support_fl"/>
    <child link="caster_wheel_fl_2"/>
    <origin rpy="0 0 0" xyz="-0.02 -0.0685 0"/>
    <axis xyz="0 0 1"/>
  </joint>
  <link name="downward_camera">
    <!-- <inertial>
                <origin xyz="${x} ${y} ${z}" rpy="0 0 0"/>
                <mass value="1.384936"/>
                <inertia ixx="0.00104" ixy="-7.659E-17" ixz="-0.000000000000008721" iyx="-7.659E-17" iyy="0.001219" iyz="-0.000010728685" izx="-0.000000000000008721" izy="-0.000010728685" izz="0.0005682"/>
            </inertial> -->
    <visual>
      <origin rpy="0 0 0" xyz="0 0 0"/>
      <geometry>
        <mesh filename="package://w3_600b/meshes/downward_camera.stl" scale="0.001 0.001 0.001"/>
      </geometry>
      <material name="silver"/>
    </visual>
    <!-- <collision>
                <origin xyz="0 0 0" rpy="0 0 0"/>
                <geometry>
                <mesh filename="package://w3_600b/meshes/bottom_camera.stl" scale="0.001 0.001 0.001"/>
                </geometry>
            </collision> -->
  </link>
  <link name="upward_camera">
    <!-- <inertial>
                <origin xyz="${x} ${y} ${z}" rpy="0 0 0"/>
                <mass value="1.384936"/>
                <inertia ixx="0.00104" ixy="-7.659E-17" ixz="-0.000000000000008721" iyx="-7.659E-17" iyy="0.001219" iyz="-0.000010728685" izx="-0.000000000000008721" izy="-0.000010728685" izz="0.0005682"/>
            </inertial> -->
    <visual>
      <origin rpy="0 0 0" xyz="0 0 0"/>
      <geometry>
        <mesh filename="package://w3_600b/meshes/upward_camera.stl" scale="0.001 0.001 0.001"/>
      </geometry>
      <material name="silver"/>
    </visual>
    <!-- <collision>
                <origin xyz="0 0 0" rpy="0 0 0"/>
                <geometry>
                <mesh filename="package://w3_600b/meshes/bottom_camera.stl" scale="0.001 0.001 0.001"/>
                </geometry>
            </collision> -->
  </link>
  <link name="front_lidar">
    <!-- <inertial>
                <origin xyz="0.423797 0.139017 0.011563" rpy="0 0 0"/>
                <mass value="0.569677"/>
                <inertia ixx="0.0009071" ixy="0.000000243534" ixz="0.000014337829" iyx="0.000000243534" iyy="0.0008086" iyz="0.000074824692" izx="0.000014337829" izy="0.000074824692" izz="0.0005095"/>
            </inertial> -->
    <visual>
      <origin rpy="0 1.57 0" xyz="0.424631 0.1165 0"/>
      <geometry>
        <mesh filename="package://w3_600b/meshes/front_lidar.stl" scale="0.001 0.001 0.001"/>
      </geometry>
      <material name="silver"/>
    </visual>
    <!-- <collision>
                <origin xyz="0.424631 0.1165 0" rpy="0 1.57 0"/>
                <geometry>
                    <mesh filename="package://w3_600b/meshes/front_lidar.stl" scale="0.001 0.001 0.001"/>
                </geometry>
            </collision> -->
  </link>
  <link name="back_lidar">
    <!-- <inertial>
                <origin xyz="0.423797 0.139017 0.011563" rpy="0 0 0"/>
                <mass value="0.569677"/>
                <inertia ixx="0.0009071" ixy="0.000000243534" ixz="0.000014337829" iyx="0.000000243534" iyy="0.0008086" iyz="0.000074824692" izx="0.000014337829" izy="0.000074824692" izz="0.0005095"/>
            </inertial> -->
    <visual>
      <origin rpy="0 0 0" xyz="0 0 0"/>
      <geometry>
        <mesh filename="package://w3_600b/meshes/back_lidar.stl" scale="0.001 0.001 0.001"/>
      </geometry>
      <material name="silver"/>
    </visual>
    <!-- <collision>
                <origin xyz="0.424631 0.1165 0" rpy="0 1.57 0"/>
                <geometry>
                    <mesh filename="package://w3_600b/meshes/front_lidar.stl" scale="0.001 0.001 0.001"/>
                </geometry>
            </collision> -->
  </link>
  <link name="left_wheel">
    <inertial>
      <origin rpy="0 0 0" xyz="-0.000216 0.057568 -0.271782"/>
      <mass value="9.185826"/>
      <inertia ixx="0.02957" ixy="-0.000044741546" ixz="0.0001326" iyx="-0.000044741546" iyy="0.03102" iyz="0.000007781675" izx="0.0001326" izy="0.000007781675" izz="0.02782"/>
    </inertial>
    <visual>
      <origin rpy="0 0 0" xyz="0 0 0.147197"/>
      <geometry>
        <mesh filename="package://w3_600b/meshes/left_wheel.stl" scale="0.001 0.001 0.001"/>
      </geometry>
      <material name="silver"/>
    </visual>
    <collision>
      <origin rpy="0 0 0" xyz="0 0 0.147197"/>
      <geometry>
        <mesh filename="package://w3_600b/meshes/left_wheel.stl" scale="0.001 0.001 0.001"/>
      </geometry>
    </collision>
  </link>
  <joint name="left_wheel_joint" type="revolute">
    <parent link="base_link"/>
    <child link="left_wheel"/>
    <origin rpy="0 0 0" xyz="0 0.0575 -0.27875"/>
    <limit effort="22" lower="-6.28" upper="6.28" velocity="219.8"/>
    <axis xyz="0 0 1"/>
  </joint>
  <link name="right_wheel">
    <inertial>
      <origin rpy="0 0 0" xyz="0.000216 0.057568 0.271782"/>
      <mass value="9.185826"/>
      <inertia ixx="0.02957" ixy="0.000044741546" ixz="0.0001326" iyx="0.000044741546" iyy="0.03102" iyz="-0.000007781675" izx="0.0001326" izy="-0.000007781675" izz="0.02782"/>
    </inertial>
    <visual>
      <origin rpy="0 0 0" xyz="0 0 0.147197"/>
      <geometry>
        <mesh filename="package://w3_600b/meshes/right_wheel.stl" scale="0.001 0.001 0.001"/>
      </geometry>
      <material name="silver"/>
    </visual>
    <collision>
      <origin rpy="0 0 0" xyz="0 0 0.147197"/>
      <geometry>
        <mesh filename="package://w3_600b/meshes/right_wheel.stl" scale="0.001 0.001 0.001"/>
      </geometry>
    </collision>
  </link>
  <joint name="right_wheel_joint" type="revolute">
    <parent link="base_link"/>
    <child link="right_wheel"/>
    <origin rpy="0 3.14 0" xyz="0 0.0575 0.27875"/>
    <limit effort="22" lower="-6.28" upper="6.28" velocity="219.8"/>
    <axis xyz="0 0 1"/>
  </joint>
  <link name="tray">
    <inertial>
      <origin rpy="0 0 0" xyz="0.000045 0.218468 -0.0000000000003836"/>
      <mass value="58.666118"/>
      <inertia ixx="2.038" ixy="0.000005613643" ixz="-0.000000000000003583" iyx="0.000005613643" iyy="5.914" iyz="-0.00000000000002564" izx="-0.000000000000003583" izy="-0.00000000000002564" izz="3.878"/>
    </inertial>
    <visual>
      <origin rpy="0 0 0" xyz="0 0 0"/>
      <geometry>
        <mesh filename="package://w3_600b/meshes/tray.stl" scale="0.001 0.001 0.001"/>
      </geometry>
      <material name="silver"/>
    </visual>
    <collision>
      <origin rpy="0 0 0" xyz="0 0 0"/>
      <geometry>
        <mesh filename="package://w3_600b/meshes/tray.stl" scale="0.001 0.001 0.001"/>
      </geometry>
    </collision>
  </link>
  <link name="rotating_base_link"/>
  <joint name="tray_revolute_joint" type="revolute">
    <parent link="base_link"/>
    <child link="rotating_base_link"/>
    <origin rpy="0 0 0" xyz="0 0 0"/>
    <axis xyz="0 1 0"/>
    <limit effort="5886" lower="-6.28" upper="6.28" velocity="5.233333333333334"/>
  </joint>
  <joint name="tray_prismatic_joint" type="prismatic">
    <parent link="rotating_base_link"/>
    <child link="tray"/>
    <origin rpy="0 0 0" xyz="0 0 0"/>
    <axis xyz="0 1 0"/>
    <limit effort="5886" lower="0" upper="0.06" velocity="0.013"/>
  </joint>
  <!-- CONTROL -->
</robot>
